Workbook

Sheet cartographie
B5: =grille_de_cotation!J1 -> Adresse :
B7: =grille_de_cotation!A1 -> Date de l'exécution : | C7: =grille_de_cotation!A2 -> /01/2025
K27: 100
K28: 85
K29: 70
B30: Nombre de KO = | C30: =grille_de_cotation!L111 -> 0 | K30: 0
B31: Amendes potentielles = | C31: =C30*450*5 -> 0
E32: Maîtrise de l'hygiène à : | I32: =(grille_de_cotation!J111)*100 -> 100 | J32: %
A34: ACTIONS CORRECTIVES ATTENDUES
A36: Ecarts constatés | D36: Actions correctives définies par le responsable | G36: Délai | H36: Réalisation | J36: Vérification
H37: Quand | I37: Visa

Sheet grille_de_cotation
A1: Date de l'exécution : | J1: Adresse :
A2: /01/2025 | B2: KO | C2: * | I2: pondération | J2: Note | K2: Commentaires | L2: Actions correctives | N2: Photo(s)
A3: 1. LOCAUX ET EQUIPEMENTS | J3: =SUM(J4:J16) -> 1
A4: Lutte contre les nuisibles | C4: 1 | H4: =SUM(C4:E4) -> 1 | I4: 0.333 | J4: =H4*I4 -> 0.333
K6: Contrat 3D en place | L6: Conforme
A10: Maintenance des locaux et équipements | C10: 1 | H10: =SUM(C10:E10) -> 1 | I10: 0.333 | J10: =H10*I10 -> 0.333
K12: Ensemble bien entretenu | L12: Conforme
A16: Nettoyage et désinfection des locaux et équipements | C16: 1 | H16: =SUM(C16:E16) -> 1 | I16: 0.334 | J16: =H16*I16 -> 0.334
K18: Produits de nettoyage conformes au plan de nettoyage affiché | L18: Conforme
K20: Enregistrement du nettoyage effectué | L20: Conforme
A22: 2. MAITRISE DES TEMPÉRATURES | J22: =SUM(J23:J30) -> 1
A23: Maîtrise du froid positif et négatif (enregistrement de températures, températures effectives, joints, givre…) | C23: 1 | H23: =SUM(C23:G23) -> 1 | I23: 0.5 | J23: =H23*I23 -> 0.5
K26: Froid maîtrisé | L26: Conforme
K28: Enregistrement des relevés de températures effectué | L28: Conforme
A30: Maîtrise du chaud (Bain-marie, friteuses, grilles de four…) | C30: 1 | H30: =SUM(C30:G30) -> 1 | I30: 0.5 | J30: =H30*I30 -> 0.5
K33: Chaud maîtrisé | L33: Conforme
K36: enregistrement des changements d'huile | L36: Conforme
A37: 3. MAITRISE DES MATIÈRES | J37: =SUM(J38:J52) -> 1
A38: Contrôle à réception | C38: 1 | H38: =SUM(C38:G38) -> 1 | I38: 0.333 | J38: =H38*I38 -> 0.333
K41: BL pris en photo avec prise de tempéature | L41: Conforme
A45: Gestions des conditionnements et emballages | C45: 1 | H45: =SUM(C45:G45) -> 1 | I45: 0.333 | J45: =H45*I45 -> 0.333
K48: Absence de cartons et emballages primaires en zone de production. Les aliments sont protégés et datés. | L48: Conforme
A52: Affichage | C52: 1 | H52: =SUM(C52:G52) -> 1 | I52: 0.334 | J52: =H52*I52 -> 0.334 | N52: vu
K55: Présence des affichages | L55: Conforme
A59: 4. TRACABILITE ET GESTION DES NON-CONFORMITES | J59: =SUM(J60:J74) -> 1
A60: Système de traçabilité (Réalisation, qualité des photos, traçabilité fonctionnelle…) | C60: 1 | H60: =SUM(C60:G60) -> 1 | I60: 0.333 | J60: =H60*I60 -> 0.333
K63: La traçabilité est fonctionnelle | L63: Conforme
A67: Gestion des non-conformités | C67: 1 | H67: =SUM(C67:G67) -> 1 | I67: 0.333 | J67: =H67*I67 -> 0.333
K70: La gestion des non-conformités est réalisée | L70: Conforme
A74: Gestion des actions correctives de l'audit précédent | C74: 1 | H74: =SUM(C74:G74) -> 1 | I74: 0.334 | J74: =H74*I74 -> 0.334
K77: Des actions correctives de l'audit précédent ont été mises en place | L77: Conforme
A81: 5. GESTION DES DECHETS ET DES SOUS-PRODUITS ANIMAUX | J81: =SUM(J82:J89) -> 1
A82: Gestion des déchets | C82: 1 | H82: =SUM(C82:G82) -> 1 | I82: 0.5 | J82: =H82*I82 -> 0.5
K85: Les déchets sont régulièrement évacués | L85: Conforme
A89: Gestions des poubelles | C89: 1 | H89: =SUM(C89:G89) -> 1 | I89: 0.5 | J89: =H89*I89 -> 0.5
K92: Présence de poubelles fermées à pédale | L92: Conforme
A96: 6. GESTION DU PERSONNEL | J96: =SUM(J97:J104) -> 1
A97: Hygiène et équipements du personnel (lave-mains et consommables, sanitaires, vestiaires…) | C97: 1 | H97: =SUM(C97:G97) -> 1 | I97: 0.5 | J97: =H97*I97 -> 0.5
K100: Tenue de travail conforme | L100: Conforme
K101: Présence de lave-mains propres avec tous les consommables, vestiaires et sanitaires propres. | L101: Conforme
...

Sheet Listes_défilantes
A1: 1. LOCAUX ET EQUIPEMENTS
A2: Lutte contre les nuisibles | B2: Contrat 3D en place | C2: Conforme
B3: Entrée potentielle de nuisibles | C3: Toutes les ouvertures doivent être fermées
C4: Mettre en place un contrat 3D
C5: Utiliser un désinsectiseur UV
A8: Maintenance des locaux et équipements | B8: Ensemble bien entretenu | C8: Conforme
B9: Joints des timbres froids détériorés | C9: Changez les joints détériorés
B10: Présence de givre excessif | C10: Dégivrez les installations de froids
B11: Carrelages cassés | C11: Remplacez le carrelage cassé
B12: Présence de rouille | C12: Prévoir des travaux de rénovation
B13: Présence de peinture écaillée
A16: Nettoyage et désinfection des locaux et équipements | B16: Produits de nettoyage conformes au plan de nettoyage affiché | C16: Conforme
B17: Ensemble propre et bien rangé
B18: Présence de salissures anciennes sous le plan de travail | C18: Effectuez un nettoyage plus approfondi notamment sous les plans de travail
B19: Présence de salissures anciennes | C19: Effectuez un nettoyage plus approfondi
B20: Enregistrement du nettoyage non effectué | C20: Effectuez l'enregistrement du nettoyage
B21: Produits non conformes | C21: Procurez vous des produits nettoyants et désinfectants
B22: Plans de nettoyage non affichés | C22: Affichez les plans de nettoyage
B23: Le matériel de nettoyage est accroché
B24: Le matériel de nettoyage est posé au sol | C24: Accrochez le matériel de nettoyage
B25: Le matériel de nettoyage est propre
B26: Le matériel de nettoyage est sale | C26: Le matériel de nettoyage doit être nettoyé et désinfecté
B27: Présence d'eau stagnante | C27: Asséchez au maximum après le nettoyage
A30: 2. MAITRISE DES TEMPÉRATURES
A31: Maîtrise du froid positif et négatif (enregistrement de températures, températures effectives, joints, givre…) | B31: Froid maîtrisé | C31: Conforme
B32: Refroidissement rapide maîtrisé
B33: Refroidissement rapide non maîtrisé | C33: La baisse de température de 65°C à 3°C doit être effectuée en moins de 2 heures et enregistrée
B34: Enregistrement du refroidissement rapide non effectué | C34: Ce contrôle est obligatoire
B35: Enregistrement du refroidissement rapide effectué
B36: Enregistrement des relevés de températures non effectué | C36: Effectuez l'enregistrement des relevés de températures
B37: Enregistrement des relevés de températures effectué
B38: Températures non conformes | C38: Effectuez une maintenance des installations de froid
B39: Présence de denrées en décongélation à température ambiante | C39: La décongélation doit être réalisée en chambre froide
A43: Maîtrise du chaud (Bain-marie, friteuses, grilles de four…) | B43: Chaud maîtrisé | C43: Conforme
B44: Températures buffets non conformes | C44: Revoir l'utilisation des buffets
B45: Température bain-marie non conforme | C45: Revoir l'utilisation du bain-marie
B46: TPM huile de friture conforme
B47: TPM huile de friture non conforme | C47: Changez l'huile immédiatement
B48: Absence de l'enregistrement des changements d'huile | C48: Enregistrer les changement d'huile
A51: 3. MAITRISE DES MATIÈRES
...

Sheet résultats
B1: SYNTHESE DES RESULTATS
A3: Bonnes Pratiques | B3: Items | C3: Notes
A4: 1 | B4: LOCAUX ET EQUIPEMENTS | C4: =grille_de_cotation!J3 -> 1
A5: 2 | B5: MAITRISE DES TEMPERATURES | C5: =grille_de_cotation!J22 -> 1
A6: 3 | B6: MAITRISE DES MATIERES | C6: =grille_de_cotation!J37 -> 1
A7: 4 | B7: TRACABILITE ET GESTION DES NON-CONFORMITES | C7: =grille_de_cotation!J59 -> 1
A8: 5 | B8: GESTION DES DECHETS ET DES SOUS-PRODUITS ANIMAUX | C8: =grille_de_cotation!J81 -> 1
A9: 6 | B9: GESTION DU PERSONNEL | C9: =grille_de_cotation!J96 -> 1
A10: NOTE TOTALE | C10: =SUM(C4:C9)/6 -> 1
